<!DOCTYPE html>
<html lang="en">
<head>
	<meta charset="UTF-8">
	<title>try</title>
</head>
<body>
	<div class="">
		异常的捕捉: try {...} catch(e){ ... } finally{...} <br>
		catch 中可以对不同类型异常进行捕捉, <br>
		eg: if (e instanceof errotype){....}  <br>
		常见异常: <br>
		1.Error 所有异常的父类,可以通过 new Error 来创建一个自定义异常 <br>
		2.EvalError: 关于eval的异常 <br>
		3.intermalError: 引擎内部出现错误(不标准) <br>
		4.RangeError: 超过最小值或最大值 <br>
		5.ReferenceError: 变量不存在 <br>
		6.SyntaxError: 语法错误 <br>
		7.TypeError: 类型错误 <br>
		8. URLError: URL解析错误 <br>
		<br><br><br>
		自定义异常:
		eg : try{ throw new Error('自定义错误提示内容','filename',行号)} <br>
					catch(e){  consolo.log(e.message)}
	</div>

	<script type="text/javascript">

		try {
			//可能会发生错误的代码
			// fun();
			console.log(a);
			console.log("------");
		} catch(e){
			//捕获到发生的错误，执行此处的代码
			console.log("catch ...");
			console.log(e);

			if (e instanceof ReferenceError){
				console.log("reference");
			} else {
				console.log("other error");
			}

		 } finally {

		 	//无论是否有错误，都会执行finally中的代码
			console.log("正常运行");
		 }





		 /***************************************************/
		 try {
		 	throw new Error("自定义错误", "09.try.html", 41);
		 } catch(e){
		 	console.log(e.message);
		 }

		 console.log("运行完毕");




	</script>
</body>
</html>
